<?xml version="1.0" ?>
<!-- =================================================================================== -->
<!-- |    This document was autogenerated by xacro from /data/basis_roboter.urdf.xacro | -->
<!-- |    EDITING THIS FILE BY HAND IS NOT RECOMMENDED                                 | -->
<!-- =================================================================================== -->
<robot name="service_roboter">
  <link name="base_link">
    <visual>
      <origin rpy="0.0 0.0 0.0" xyz="0.0 0.0 0.0"/>
      <geometry>
        <box size="0.01 0.01 0.01"/>
      </geometry>
      <material name="Cyan">
        <color rgba="0 0.9 0.9 1.0"/>
      </material>
    </visual>
  </link>
  <link name="table_link">
    <visual>
      <origin rpy="0.0 0.0 0.0" xyz="2.0 0.75 -0.0125"/>
      <geometry>
        <box size="4.0 1.5 0.025"/>
      </geometry>
    </visual>
  </link>
  <joint name="table_joint" type="fixed">
    <parent link="base_link"/>
    <child link="table_link"/>
    <origin rpy="0.0 0.0 0.0" xyz="0.0 0.0 0.0"/>
  </joint>
  <link name="head_link">
    <visual>
      <origin rpy="0.0 0.0 0.0" xyz="0.05 0.1 0.0075"/>
      <geometry>
        <box size="0.1 0.2 0.015"/>
      </geometry>
      <material name="Cyan">
        <color rgba="0.9 0.0 0.0 1.0"/>
      </material>
    </visual>
  </link>
  <joint name="head_joint" type="fixed">
    <parent link="head_z_link"/>
    <child link="head_link"/>
    <origin rpy="0.0 0.0 0.0" xyz="0.0 0.0 0.0"/>
  </joint>
  <link name="head_x_link">
    <visual>
      <origin rpy="0.0 0.0 0.0" xyz="0.0 0.0 0.0"/>
      <geometry>
        <box size="0.01 0.01 0.01"/>
      </geometry>
      <material name="Cyan">
        <color rgba="0 0.9 0.9 1.0"/>
      </material>
    </visual>
  </link>
  <joint name="head_x_joint" type="prismatic">
    <parent link="base_link"/>
    <child link="head_x_link"/>
    <axis xyz="1.0 0.0 0.0"/>
    <limit effort="1000.0" lower="0.0" upper="3.9" velocity="0.5"/>
    <origin rpy="0.0 0.0 0.0" xyz="0.0 0.0 0.0"/>
  </joint>
  <link name="head_y_link">
    <visual>
      <origin rpy="0.0 0.0 0.0" xyz="0.0 0.0 0.0"/>
      <geometry>
        <box size="0.01 0.01 0.01"/>
      </geometry>
      <material name="Cyan">
        <color rgba="0 0.9 0.9 1.0"/>
      </material>
    </visual>
  </link>
  <joint name="head_y_joint" type="prismatic">
    <parent link="head_x_link"/>
    <child link="head_y_link"/>
    <axis xyz="0.0 1.0 0.0"/>
    <limit effort="1000.0" lower="0.0" upper="1.3" velocity="0.5"/>
    <origin rpy="0.0 0.0 0.0" xyz="0.0 0.0 0.0"/>
  </joint>
  <link name="head_z_link">
    <visual>
      <origin rpy="0.0 0.0 0.0" xyz="0.0 0.0 0.0"/>
      <geometry>
        <box size="0.01 0.01 0.01"/>
      </geometry>
      <material name="Cyan">
        <color rgba="0 0.9 0.9 1.0"/>
      </material>
    </visual>
  </link>
  <joint name="head_z_joint" type="prismatic">
    <parent link="head_y_link"/>
    <child link="head_z_link"/>
    <axis xyz="0.0 0.0 1.0"/>
    <limit effort="1000.0" lower="0.0" upper="0.6" velocity="0.5"/>
    <origin rpy="0.0 0.0 0.0" xyz="0.0 0.0 0.0"/>
  </joint>
  <link name="sled_right_link">
    <visual>
      <origin rpy="0.0 0.0 0.0" xyz="0.05 -0.0075 0.19999999999999998"/>
      <geometry>
        <box size="0.1 0.015 0.5"/>
      </geometry>
      <material name="Cyan">
        <color rgba="0.9 0.9 0.0 1.0"/>
      </material>
    </visual>
  </link>
  <joint name="sled_right_joint" type="fixed">
    <parent link="head_x_link"/>
    <child link="sled_right_link"/>
    <origin rpy="0.0 0.0 0.0" xyz="0.0 0.0 0.0"/>
  </joint>
  <link name="sled_left_link">
    <visual>
      <origin rpy="0.0 0.0 0.0" xyz="0.05 1.5075 0.19999999999999998"/>
      <geometry>
        <box size="0.1 0.015 0.5"/>
      </geometry>
      <material name="Cyan">
        <color rgba="0.9 0.9 0.0 1.0"/>
      </material>
    </visual>
  </link>
  <joint name="sled_left_joint" type="fixed">
    <parent link="head_x_link"/>
    <child link="sled_left_link"/>
    <origin rpy="0.0 0.0 0.0" xyz="0.0 0.0 0.0"/>
  </joint>
</robot>
