<?xml version="1.0" ?>
<!-- =================================================================================== -->
<!-- |    This document was autogenerated by xacro from /data/service_roboter.urdf.xacro | -->
<!-- |    EDITING THIS FILE BY HAND IS NOT RECOMMENDED                                 | -->
<!-- =================================================================================== -->
<robot name="service_roboter">
  <link name="base_link"/>
  <link name="barrel_link">
    <visual>
      <origin rpy="0.0 0.0 0.0" xyz="0.0 0.0 0.45"/>
      <geometry>
        <cylinder length="0.9" radius="0.29"/>
      </geometry>
    </visual>
    <collision>
      <origin rpy="0.0 0.0 0.0" xyz="0.0 0.0 0.45"/>
      <geometry>
        <cylinder length="0.9" radius="0.29"/>
      </geometry>
    </collision>
  </link>
  <joint name="barrel_joint" type="fixed">
    <parent link="base_link"/>
    <child link="barrel_link"/>
    <origin rpy="0.0 0.0 0.0" xyz="0.0 0.0 0.0"/>
  </joint>
  <link name="wheel_left_link">
    <visual>
      <origin rpy="1.5707963267948966 0.0 0.0" xyz="0.0 0.0 0.0"/>
      <geometry>
        <cylinder length="0.05" radius="0.15"/>
      </geometry>
    </visual>
  </link>
  <joint name="wheel_left_joint" type="continuous">
    <parent link="base_link"/>
    <child link="wheel_left_link"/>
    <axis xyz="0 1 0"/>
    <origin rpy="0.0 0.0 0.0" xyz="0.0 0.145 0.09999999999999999"/>
  </joint>
  <link name="wheel_right_link">
    <visual>
      <origin rpy="1.5707963267948966 0.0 0.0" xyz="0.0 0.0 0.0"/>
      <geometry>
        <cylinder length="0.05" radius="0.15"/>
      </geometry>
    </visual>
  </link>
  <joint name="wheel_right_joint" type="continuous">
    <parent link="base_link"/>
    <child link="wheel_right_link"/>
    <axis xyz="1 0 0"/>
    <origin rpy="0.0 0.0 0.0" xyz="0.0 -0.145 0.09999999999999999"/>
  </joint>
</robot>
